ProgrammingError
sqlalchemy.exc.ProgrammingError: (psycopg2.errors.UndefinedColumn) column audit_log.log_file does not exist
LINE 1: ..._timestamp, audit_log.status AS audit_log_status, audit_log....
                                                             ^

[SQL: SELECT audit_log.id AS audit_log_id, audit_log.user_id AS audit_log_user_id, audit_log.filename AS audit_log_filename, audit_log.timestamp AS audit_log_timestamp, audit_log.status AS audit_log_status, audit_log.log_file AS audit_log_log_file 
FROM audit_log 
WHERE audit_log.user_id = %(user_id_1)s ORDER BY audit_log.timestamp DESC]
[parameters: {'user_id_1': 1}]
(Background on this error at: https://sqlalche.me/e/20/f405)

Traceback (most recent call last)
File "/home/runner/StockTradeMiddlewareApp/.pythonlibs/lib/python3.11/site-packages/sqlalchemy/engine/base.py", line 1967, in _exec_single_context
self.dialect.do_execute(
^
File "/home/runner/StockTradeMiddlewareApp/.pythonlibs/lib/python3.11/site-packages/sqlalchemy/engine/default.py", line 941, in do_execute
cursor.execute(statement, parameters)
^^^^^^^^^^^^^^^^^^^^^^^^^^^^^^^^^^^^^
The above exception was the direct cause of the following exception:
File "/home/runner/StockTradeMiddlewareApp/.pythonlibs/lib/python3.11/site-packages/flask/app.py", line 1498, in __call__
    ) -> cabc.Iterable[bytes]:
        """The WSGI server calls the Flask application object as the
        WSGI application. This calls :meth:`wsgi_app`, which can be
        wrapped to apply middleware.
        """
        return self.wsgi_app(environ, start_response)
               ^^^^^^^^^^^^^^^^^^^^^^^^^^^^^^^^^^^^^^
File "/home/runner/StockTradeMiddlewareApp/.pythonlibs/lib/python3.11/site-packages/flask_socketio/__init__.py", line 43, in __call__
return super(_SocketIOMiddleware, self).__call__(environ,
       ^^^^^^^^^^^^^^^^^^^^^^^^^^^^^^^^^^^^^^^^^^^^^^^^^^^^^^^^^
File "/home/runner/StockTradeMiddlewareApp/.pythonlibs/lib/python3.11/site-packages/engineio/middleware.py", line 74, in __call__
return self.wsgi_app(environ, start_response)
       ^^^^^^^^^^^^^^^^^^^^^^^^^^^^^^^^^^^^^^
File "/home/runner/StockTradeMiddlewareApp/.pythonlibs/lib/python3.11/site-packages/flask/app.py", line 1476, in wsgi_app
response = self.handle_exception(e)
           ^^^^^^^^^^^^^^^^^^^^^^^^
File "/home/runner/StockTradeMiddlewareApp/.pythonlibs/lib/python3.11/site-packages/flask/app.py", line 1473, in wsgi_app
response = self.full_dispatch_request()
           ^^^^^^^^^^^^^^^^^^^^^^^^^^^^
File "/home/runner/StockTradeMiddlewareApp/.pythonlibs/lib/python3.11/site-packages/flask/app.py", line 882, in full_dispatch_request
rv = self.handle_user_exception(e)
     ^^^^^^^^^^^^^^^^^^^^^^^^^^^^^
File "/home/runner/StockTradeMiddlewareApp/.pythonlibs/lib/python3.11/site-packages/flask/app.py", line 880, in full_dispatch_request
rv = self.dispatch_request()
     ^^^^^^^^^^^^^^^^^^^^^^^
File "/home/runner/StockTradeMiddlewareApp/.pythonlibs/lib/python3.11/site-packages/flask/app.py", line 865, in dispatch_request
return self.ensure_sync(self.view_functions[rule.endpoint])(**view_args)  # type: ignore[no-any-return]
       ^^^^^^^^^^^^^^^^^^^^^^^^^^^^^^^^^^^^^^^^^^^^^^^^^^^^^^^^^^^^^^^^^
File "/home/runner/StockTradeMiddlewareApp/.pythonlibs/lib/python3.11/site-packages/flask_login/utils.py", line 290, in decorated_view
return current_app.ensure_sync(func)(*args, **kwargs)
       ^^^^^^^^^^^^^^^^^^^^^^^^^^^^^^^^^^^^^^^^^^^^^^
File "/home/runner/StockTradeMiddlewareApp/app.py", line 220, in audit_trail
logs = AuditLog.query.filter_by(user_id=current_user.id).order_by(AuditLog.timestamp.desc()).all()
       ^^^^^^^^^^^^^^^^^^^^^^^^^^^^^^^^^^^^^^^^^^^^^^^^^^^^^^^^^^^^^^^^^^^^^^^^^^^^^^^^^^^^^^^^^^^
File "/home/runner/StockTradeMiddlewareApp/.pythonlibs/lib/python3.11/site-packages/sqlalchemy/orm/query.py", line 2673, in all
return self._iter().all()  # type: ignore
       ^^^^^^^^^^^^
File "/home/runner/StockTradeMiddlewareApp/.pythonlibs/lib/python3.11/site-packages/sqlalchemy/orm/query.py", line 2827, in _iter
result: Union[ScalarResult[_T], Result[_T]] = self.session.execute(
                                              
File "/home/runner/StockTradeMiddlewareApp/.pythonlibs/lib/python3.11/site-packages/sqlalchemy/orm/session.py", line 2362, in execute
return self._execute_internal(
       
File "/home/runner/StockTradeMiddlewareApp/.pythonlibs/lib/python3.11/site-packages/sqlalchemy/orm/session.py", line 2247, in _execute_internal
result: Result[Any] = compile_state_cls.orm_execute_statement(
                      
File "/home/runner/StockTradeMiddlewareApp/.pythonlibs/lib/python3.11/site-packages/sqlalchemy/orm/context.py", line 305, in orm_execute_statement
result = conn.execute(
         
File "/home/runner/StockTradeMiddlewareApp/.pythonlibs/lib/python3.11/site-packages/sqlalchemy/engine/base.py", line 1418, in execute
return meth(
       
File "/home/runner/StockTradeMiddlewareApp/.pythonlibs/lib/python3.11/site-packages/sqlalchemy/sql/elements.py", line 515, in _execute_on_connection
return connection._execute_clauseelement(
       
File "/home/runner/StockTradeMiddlewareApp/.pythonlibs/lib/python3.11/site-packages/sqlalchemy/engine/base.py", line 1640, in _execute_clauseelement
ret = self._execute_context(
      
File "/home/runner/StockTradeMiddlewareApp/.pythonlibs/lib/python3.11/site-packages/sqlalchemy/engine/base.py", line 1846, in _execute_context
return self._exec_single_context(
       
File "/home/runner/StockTradeMiddlewareApp/.pythonlibs/lib/python3.11/site-packages/sqlalchemy/engine/base.py", line 1986, in _exec_single_context
self._handle_dbapi_exception(
^
File "/home/runner/StockTradeMiddlewareApp/.pythonlibs/lib/python3.11/site-packages/sqlalchemy/engine/base.py", line 2355, in _handle_dbapi_exception
raise sqlalchemy_exception.with_traceback(exc_info[2]) from e
^^^^^^^^^^^^^^^^^^^^^^^^^^^^^^^^^^^^^^^^^^^^^^^^^^^^^^^^^^^^^
File "/home/runner/StockTradeMiddlewareApp/.pythonlibs/lib/python3.11/site-packages/sqlalchemy/engine/base.py", line 1967, in _exec_single_context
self.dialect.do_execute(
^
File "/home/runner/StockTradeMiddlewareApp/.pythonlibs/lib/python3.11/site-packages/sqlalchemy/engine/default.py", line 941, in do_execute
cursor.execute(statement, parameters)
^^^^^^^^^^^^^^^^^^^^^^^^^^^^^^^^^^^^^
sqlalchemy.exc.ProgrammingError: (psycopg2.errors.UndefinedColumn) column audit_log.log_file does not exist
LINE 1: ..._timestamp, audit_log.status AS audit_log_status, audit_log....
^

[SQL: SELECT audit_log.id AS audit_log_id, audit_log.user_id AS audit_log_user_id, audit_log.filename AS audit_log_filename, audit_log.timestamp AS audit_log_timestamp, audit_log.status AS audit_log_status, audit_log.log_file AS audit_log_log_file
FROM audit_log
WHERE audit_log.user_id = %(user_id_1)s ORDER BY audit_log.timestamp DESC]
[parameters: {'user_id_1': 1}]
(Background on this error at: https://sqlalche.me/e/20/f405)
The debugger caught an exception in your WSGI application. You can now look at the traceback which led to the error.
To switch between the interactive traceback and the plaintext one, you can click on the "Traceback" headline. From the text traceback you can also create a paste of it.

Brought to you by DON'T PANIC, your friendly Werkzeug powered traceback interpreter.